Workbook

Sheet Dados
A1: DATA_REL | B1: TP_DESP | C1: CNPJ_CPF | D1: NOME | E1: REFERÊNCIA | F1: NF | G1: VR_UNIT | H1: DIAS | I1: VALOR | J1: DT_VENCTO | K1: CATEGORIA | L1: DADOS_BANCARIOS | M1: OBSERVAÇÃO | N1: NF? | O1: PAGTO | P1: CHECK | Q1: RELATÓRIO
A2: 45540 | B2: 1 | C2: 14758063613 | D2: IZAEL BISPO OLIVEIRA | E2: DIÁRIA | G2: 200 | H2: 3 | I2: 600 | J2: 06/09/2024 | K2: MO | L2: PIX: 14758063613 | N2: =IF(ISERROR(SEARCH("NF",E2,1)),"NÃO","SIM") | O2: =IF($B2=5,"SIM","") | P2: =A2&B2&C2&E2&G2&EDATE(J2,0) | Q2: =IF(A2=0,"",VLOOKUP($A2,RESUMO!$A$8:$B$83,2,FALSE))
A3: 45540 | B3: 1 | C3: 14020156662 | D3: WELLINGTON GOMES PAIVA | E3: DIÁRIA | G3: 200 | H3: 1 | I3: 200 | J3: 06/09/2024 | K3: MO | L3: PIX: 14020156662 | N3: =IF(ISERROR(SEARCH("NF",E3,1)),"NÃO","SIM") | O3: =IF($B3=5,"SIM","") | P3: =A3&B3&C3&E3&G3&EDATE(J3,0) | Q3: =IF(A3=0,"",VLOOKUP($A3,RESUMO!$A$8:$B$83,2,FALSE))
A4: 45540 | B4: 1 | C4: 12095122623 | D4: WANDERSON ROMUALDO DE SOUZA | E4: DIÁRIA | G4: 200 | H4: 5 | I4: 1000 | J4: 06/09/2024 | K4: MO | L4: PIX: 12095122623 | N4: =IF(ISERROR(SEARCH("NF",E4,1)),"NÃO","SIM") | O4: =IF($B4=5,"SIM","") | P4: =A4&B4&C4&E4&G4&EDATE(J4,0) | Q4: =IF(A4=0,"",VLOOKUP($A4,RESUMO!$A$8:$B$83,2,FALSE))
A5: 45540 | B5: 2 | C5: 07834753000141 | D5: ANCORA PAPELARIA | E5: PLOTAGENS - NF A EMITIR | G5: 432 | I5: 432 | J5: 06/09/2024 | K5: SERV | L5: PIX: ancorapapelaria@gmail.com | N5: =IF(ISERROR(SEARCH("NF",E5,1)),"NÃO","SIM") | O5: =IF($B5=5,"SIM","") | P5: =A5&B5&C5&E5&G5&EDATE(J5,0) | Q5: =IF(A5=0,"",VLOOKUP($A5,RESUMO!$A$8:$B$83,2,FALSE))
A6: 45540 | B6: 2 | C6: 07834753000141 | D6: ANCORA PAPELARIA | E6: PLOTAGENS - NF A EMITIR | G6: 76 | I6: 76 | J6: 06/09/2024 | K6: SERV | L6: PIX: ancorapapelaria@gmail.com | N6: =IF(ISERROR(SEARCH("NF",E6,1)),"NÃO","SIM") | O6: =IF($B6=5,"SIM","") | P6: =A6&B6&C6&E6&G6&EDATE(J6,0) | Q6: =IF(A6=0,"",VLOOKUP($A6,RESUMO!$A$8:$B$83,2,FALSE))
A7: 45540 | B7: 2 | C7: 73586986653 | D7: RICARDO JOSE ELOY | E7: MARCAÇÃO DE TOPOGRAFIA | G7: 2000 | I7: 2000 | J7: 06/09/2024 | K7: SERV | L7: ITAÚ 5636 118738 - CPF: 73.586.986.6-53 | N7: =IF(ISERROR(SEARCH("NF",E7,1)),"NÃO","SIM") | O7: =IF($B7=5,"SIM","") | P7: =A7&B7&C7&E7&G7&EDATE(J7,0) | Q7: =IF(A7=0,"",VLOOKUP($A7,RESUMO!$A$8:$B$83,2,FALSE))
A8: 45540 | B8: 3 | C8: 46423467000145 | D8: MR DESENTUPIDORA | E8: BANHEIRO QUIMICO - NF 1189 | G8: 1300 | I8: 1300 | J8: 16/09/2024 | K8: MAT | N8: =IF(ISERROR(SEARCH("NF",E8,1)),"NÃO","SIM") | O8: =IF($B8=5,"SIM","") | P8: =A8&B8&C8&E8&G8&EDATE(J8,0) | Q8: =IF(A8=0,"",VLOOKUP($A8,RESUMO!$A$8:$B$83,2,FALSE))
A9: 45540 | B9: 4 | C9: 27648990687 | D9: ROGÉRIO VASCONCELOS SANTOS | E9: REGISTRO DE IMÓVEIS 24/05 - REEMBOLSO | G9: 38.77 | I9: 38.77 | J9: 24/05/2024 | K9: MO | L9: PIX: 31995901635 | N9: =IF(ISERROR(SEARCH("NF",E9,1)),"NÃO","SIM") | O9: =IF($B9=5,"SIM","") | P9: =A9&B9&C9&E9&G9&EDATE(J9,0) | Q9: =IF(A9=0,"",VLOOKUP($A9,RESUMO!$A$8:$B$83,2,FALSE))
A10: 45540 | B10: 5 | C10: 43828098000182 | D10: MADESCOM MADEIREIRA | E10: PONTALETE - PED. 47.192 | G10: 1265 | I10: 1265 | J10: 16/08/2024 | K10: MAT | N10: =IF(ISERROR(SEARCH("NF",E10,1)),"NÃO","SIM") | O10: =IF($B10=5,"SIM","") | P10: =A10&B10&C10&E10&G10&EDATE(J10,0) | Q10: =IF(A10=0,"",VLOOKUP($A10,RESUMO!$A$8:$B$83,2,FALSE))
A11: 45540 | B11: 5 | C11: 18850040000279 | D11: CASA DAS LONAS LTDA | E11: LONA AGRICOLA - NF 28110 | G11: 1788 | I11: 1788 | J11: 21/08/2024 | K11: MAT | N11: =IF(ISERROR(SEARCH("NF",E11,1)),"NÃO","SIM") | O11: =IF($B11=5,"SIM","") | P11: =A11&B11&C11&E11&G11&EDATE(J11,0) | Q11: =IF(A11=0,"",VLOOKUP($A11,RESUMO!$A$8:$B$83,2,FALSE))
A12: 45540 | B12: 5 | C12: 15746193000100 | D12: TRILHA DE MINAS | E12: SINAL - 30% TERRAPLANAGEM | G12: 70000 | I12: 70000 | J12: 29/08/2024 | K12: SERV | N12: =IF(ISERROR(SEARCH("NF",E12,1)),"NÃO","SIM") | O12: =IF($B12=5,"SIM","") | P12: =A12&B12&C12&E12&G12&EDATE(J12,0) | Q12: =IF(A12=0,"",VLOOKUP($A12,RESUMO!$A$8:$B$83,2,FALSE))
A13: 45540 | B13: 7 | C13: 30104762000107 | D13: VASCONCELOS & RINALDI ENGENHARIA | E13: ADM 13% - NF A EMITIR | G13: 10230.97 | I13: 10230.97 | J13: 06/09/2024 | K13: ADM | L13: PIX: 30104762000107 | N13: =IF(ISERROR(SEARCH("NF",E13,1)),"NÃO","SIM") | O13: =IF($B13=5,"SIM","") | P13: =A13&B13&C13&E13&G13&EDATE(J13,0) | Q13: =IF(A13=0,"",VLOOKUP($A13,RESUMO!$A$8:$B$83,2,FALSE))
A14: 45555 | B14: 1 | C14: 14758063613 | D14: IZAEL BISPO OLIVEIRA | E14: DIÁRIA | G14: 200 | H14: 10 | I14: 2000 | J14: 20/09/2024 | K14: MO | L14: PIX: 14758063613 | N14: =IF(ISERROR(SEARCH("NF",E14,1)),"NÃO","SIM") | O14: =IF($B14=5,"SIM","") | P14: =A14&B14&C14&E14&G14&EDATE(J14,0) | Q14: =IF(A14=0,"",VLOOKUP($A14,RESUMO!$A$8:$B$83,2,FALSE))
A15: 45555 | B15: 1 | C15: 31699502668 | D15: ANTONIO ZEFERINO LEANDRO | E15: DIÁRIA | G15: 200 | H15: 7 | I15: 1400 | J15: 20/09/2024 | K15: MO | L15: PIX: 31699502668 | N15: =IF(ISERROR(SEARCH("NF",E15,1)),"NÃO","SIM") | O15: =IF($B15=5,"SIM","") | P15: =A15&B15&C15&E15&G15&EDATE(J15,0) | Q15: =IF(A15=0,"",VLOOKUP($A15,RESUMO!$A$8:$B$83,2,FALSE))
A16: 45555 | B16: 2 | C16: 73586986653 | D16: RICARDO JOSE ELOY | E16: MARCAÇÃO DE TOPOGRAFIA | G16: 1200 | I16: 1200 | J16: 20/09/2024 | K16: SERV | L16: ITAÚ 5636 118738 - CPF: 73.586.986.6-53 | N16: =IF(ISERROR(SEARCH("NF",E16,1)),"NÃO","SIM") | O16: =IF($B16=5,"SIM","") | P16: =A16&B16&C16&E16&G16&EDATE(J16,0) | Q16: =IF(A16=0,"",VLOOKUP($A16,RESUMO!$A$8:$B$83,2,FALSE))
A17: 45555 | B17: 3 | C17: 32392731000116 | D17: DEPÓSITO 040 | E17: MATERIAIS DIVERSOS - NF 1323 | G17: 967.3 | I17: 967.3 | J17: 27/09/2024 | K17: MAT | N17: =IF(ISERROR(SEARCH("NF",E17,1)),"NÃO","SIM") | O17: =IF($B17=5,"SIM","") | P17: =A17&B17&C17&E17&G17&EDATE(J17,0) | Q17: =IF(A17=0,"",VLOOKUP($A17,RESUMO!$A$8:$B$83,2,FALSE))
A18: 45555 | B18: 5 | C18: 15746193000100 | D18: TRILHA DE MINAS | E18: SERVIÇO TERRAPLANGEM - NF 512 | G18: 60000 | I18: 60000 | J18: 11/09/2024 | K18: SERV | N18: =IF(ISERROR(SEARCH("NF",E18,1)),"NÃO","SIM") | O18: =IF($B18=5,"SIM","") | P18: =A18&B18&C18&E18&G18&EDATE(J18,0) | Q18: =IF(A18=0,"",VLOOKUP($A18,RESUMO!$A$8:$B$83,2,FALSE))
A19: 45555 | B19: 5 | C19: 00064354600 | D19: ORIDES ELOI DE OLIVEIRA NETO | E19: RETIRADA CORTINAS | G19: 5134 | I19: 5134 | J19: 12/09/2024 | K19: SERV | N19: =IF(ISERROR(SEARCH("NF",E19,1)),"NÃO","SIM") | O19: =IF($B19=5,"SIM","") | P19: =A19&B19&C19&E19&G19&EDATE(J19,0) | Q19: =IF(A19=0,"",VLOOKUP($A19,RESUMO!$A$8:$B$83,2,FALSE))
A20: 45555 | B20: 5 | C20: 10272028000131 | D20: MASTER SOUND | E20: RETIRADA EQUIP. AUDIO | G20: 890 | I20: 890 | J20: 12/09/2024 | K20: MAT | N20: =IF(ISERROR(SEARCH("NF",E20,1)),"NÃO","SIM") | O20: =IF($B20=5,"SIM","") | P20: =A20&B20&C20&E20&G20&EDATE(J20,0) | Q20: =IF(A20=0,"",VLOOKUP($A20,RESUMO!$A$8:$B$83,2,FALSE))
A21: 45555 | B21: 5 | C21: 04704622000151 | D21: PROJETART MOVEIS | E21: DESMONTAGEM MOVEIS - NF 152 | G21: 1600 | I21: 1600 | J21: 13/09/2024 | K21: MAT | N21: =IF(ISERROR(SEARCH("NF",E21,1)),"NÃO","SIM") | O21: =IF($B21=5,"SIM","") | P21: =A21&B21&C21&E21&G21&EDATE(J21,0) | Q21: =IF(A21=0,"",VLOOKUP($A21,RESUMO!$A$8:$B$83,2,FALSE))
A22: 45555 | B22: 7 | C22: 30104762000107 | D22: VASCONCELOS & RINALDI ENGENHARIA | E22: ADM 13% - NF A EMITIR | G22: 9514.87 | I22: 9514.87 | J22: 20/09/2024 | K22: ADM | L22: PIX: 30104762000107 | N22: =IF(ISERROR(SEARCH("NF",E22,1)),"NÃO","SIM") | O22: =IF($B22=5,"SIM","") | P22: =A22&B22&C22&E22&G22&EDATE(J22,0) | Q22: =IF(A22=0,"",VLOOKUP($A22,RESUMO!$A$8:$B$83,2,FALSE))
A23: 45570 | B23: 1 | C23: 14758063613 | D23: IZAEL BISPO OLIVEIRA | E23: DIÁRIA | G23: 200 | H23: 10 | I23: 2000 | J23: 04/10/2024 | K23: MO | L23: PIX: 14758063613 | N23: =IF(ISERROR(SEARCH("NF",E23,1)),"NÃO","SIM") | O23: =IF($B23=5,"SIM","") | P23: =A23&B23&C23&E23&G23&EDATE(J23,0) | Q23: =IF(A23=0,"",VLOOKUP($A23,RESUMO!$A$8:$B$83,2,FALSE))
A24: 45570 | B24: 2 | C24: 07834753000141 | D24: ANCORA PAPELARIA | E24: PLOTAGENS - NF A EMITIR | G24: 572 | I24: 572 | J24: 04/10/2024 | K24: SERV | L24: PIX: ancorapapelaria@gmail.com | N24: =IF(ISERROR(SEARCH("NF",E24,1)),"NÃO","SIM") | O24: =IF($B24=5,"SIM","") | P24: =A24&B24&C24&E24&G24&EDATE(J24,0) | Q24: =IF(A24=0,"",VLOOKUP($A24,RESUMO!$A$8:$B$83,2,FALSE))
A25: 45570 | B25: 2 | C25: 00000011207 | D25: MOTOBOY | E25: COMPETENCIA 09/2024 | G25: 135 | I25: 135 | J25: 04/10/2024 | K25: DIV | L25: PIX: 31995901635 | N25: =IF(ISERROR(SEARCH("NF",E25,1)),"NÃO","SIM") | O25: =IF($B25=5,"SIM","") | P25: =A25&B25&C25&E25&G25&EDATE(J25,0) | Q25: =IF(A25=0,"",VLOOKUP($A25,RESUMO!$A$8:$B$83,2,FALSE))
A26: 45570 | B26: 3 | C26: 42979237000378 | D26: TECFER COM E IND DE FERRO E MAT CONSTR LTDA | E26: TELHA, PREGO, ARAME - NF A EMITIR | G26: 5197.39 | I26: 5197.39 | J26: 04/10/2024 | K26: MAT | N26: =IF(ISERROR(SEARCH("NF",E26,1)),"NÃO","SIM") | O26: =IF($B26=5,"SIM","") | P26: =A26&B26&C26&E26&G26&EDATE(J26,0) | Q26: =IF(A26=0,"",VLOOKUP($A26,RESUMO!$A$8:$B$83,2,FALSE))
A27: 45570 | B27: 3 | C27: 46423467000145 | D27: MR DESENTUPIDORA | E27: LOCAÇÃO DE BANHEIRO - FL 1392 | G27: 1300 | I27: 1300 | J27: 16/10/2024 | K27: MAT | N27: =IF(ISERROR(SEARCH("NF",E27,1)),"NÃO","SIM") | O27: =IF($B27=5,"SIM","") | P27: =A27&B27&C27&E27&G27&EDATE(J27,0) | Q27: =IF(A27=0,"",VLOOKUP($A27,RESUMO!$A$8:$B$83,2,FALSE))
A28: 45570 | B28: 3 | C28: 07409393000130 | D28: LOCFER | E28: MARTELO - NF 26128 | G28: 320 | I28: 320 | J28: 17/10/2024 | K28: LOC | N28: =IF(ISERROR(SEARCH("NF",E28,1)),"NÃO","SIM") | O28: =IF($B28=5,"SIM","") | P28: =A28&B28&C28&E28&G28&EDATE(J28,0) | Q28: =IF(A28=0,"",VLOOKUP($A28,RESUMO!$A$8:$B$83,2,FALSE))
A29: 45570 | B29: 5 | C29: 03891863683 | D29: LEANDRO ALVES | E29: ELETRICISTA | G29: 400 | I29: 400 | J29: 17/09/2024 | K29: SERV | N29: =IF(ISERROR(SEARCH("NF",E29,1)),"NÃO","SIM") | O29: =IF($B29=5,"SIM","") | P29: =A29&B29&C29&E29&G29&EDATE(J29,0) | Q29: =IF(A29=0,"",VLOOKUP($A29,RESUMO!$A$8:$B$83,2,FALSE))
A30: 45570 | B30: 5 | C30: 15746193000100 | D30: TRILHA DE MINAS | E30: TERRAPLANAGEM - NF 520 | G30: 135250 | I30: 135250 | J30: 25/09/2024 | K30: SERV | N30: =IF(ISERROR(SEARCH("NF",E30,1)),"NÃO","SIM") | O30: =IF($B30=5,"SIM","") | P30: =A30&B30&C30&E30&G30&EDATE(J30,0) | Q30: =IF(A30=0,"",VLOOKUP($A30,RESUMO!$A$8:$B$83,2,FALSE))
A31: 45570 | B31: 7 | C31: 30104762000107 | D31: VASCONCELOS & RINALDI ENGENHARIA | E31: ADM 13% - NF A EMITIR | G31: 18872.67 | I31: 18872.67 | J31: 04/10/2024 | K31: ADM | L31: PIX: 30104762000107 | N31: =IF(ISERROR(SEARCH("NF",E31,1)),"NÃO","SIM") | O31: =IF($B31=5,"SIM","") | P31: =A31&B31&C31&E31&G31&EDATE(J31,0) | Q31: =IF(A31=0,"",VLOOKUP($A31,RESUMO!$A$8:$B$83,2,FALSE))
A32: 45585 | B32: 1 | C32: 07573876670 | D32: BRUNO JUNIO DA SILVA | E32: SALÁRIO | G32: 2080 | I32: 2080 | J32: 18/10/2024 | K32: MO | L32: PIX: 07573876670 | N32: =IF(ISERROR(SEARCH("NF",E32,1)),"NÃO","SIM") | O32: =IF($B32=5,"SIM","") | P32: =A32&B32&C32&E32&G32&EDATE(J32,0) | Q32: =IF(A32=0,"",VLOOKUP($A32,RESUMO!$A$8:$B$83,2,FALSE))
A33: 45585 | B33: 1 | C33: 00354432605 | D33: ANTONIO DUTRA DE FREITAS | E33: SALÁRIO | G33: 883.84 | I33: 883.84 | J33: 18/10/2024 | K33: MO | L33: PIX: 31982618378 | N33: =IF(ISERROR(SEARCH("NF",E33,1)),"NÃO","SIM") | O33: =IF($B33=5,"SIM","") | P33: =A33&B33&C33&E33&G33&EDATE(J33,0) | Q33: =IF(A33=0,"",VLOOKUP($A33,RESUMO!$A$8:$B$83,2,FALSE))
A34: 45585 | B34: 1 | C34: 07249031600 | D34: EDER PEREIRA DA SILVA | E34: SALÁRIO | G34: 883.84 | I34: 883.84 | J34: 18/10/2024 | K34: MO | L34: PIX: 07249031600 | N34: =IF(ISERROR(SEARCH("NF",E34,1)),"NÃO","SIM") | O34: =IF($B34=5,"SIM","") | P34: =A34&B34&C34&E34&G34&EDATE(J34,0) | Q34: =IF(A34=0,"",VLOOKUP($A34,RESUMO!$A$8:$B$83,2,FALSE))
A35: 45585 | B35: 1 | C35: 14758063613 | D35: IZAEL BISPO OLIVEIRA | E35: SALÁRIO | G35: 883.84 | I35: 883.84 | J35: 18/10/2024 | K35: MO | L35: PIX: 14758063613 | N35: =IF(ISERROR(SEARCH("NF",E35,1)),"NÃO","SIM") | O35: =IF($B35=5,"SIM","") | P35: =A35&B35&C35&E35&G35&EDATE(J35,0) | Q35: =IF(A35=0,"",VLOOKUP($A35,RESUMO!$A$8:$B$83,2,FALSE))
A36: 45585 | B36: 1 | C36: 85086894387 | D36: ROBEVAL PORTACIO DOS SANTOS | E36: SALÁRIO | G36: 514.24 | I36: 514.24 | J36: 18/10/2024 | K36: MO | L36: PIX: 31971706400 | N36: =IF(ISERROR(SEARCH("NF",E36,1)),"NÃO","SIM") | O36: =IF($B36=5,"SIM","") | P36: =A36&B36&C36&E36&G36&EDATE(J36,0) | Q36: =IF(A36=0,"",VLOOKUP($A36,RESUMO!$A$8:$B$83,2,FALSE))
A37: 45585 | B37: 1 | C37: 87942119653 | D37: DOMINGOS DA SILVA LIMA | E37: SALÁRIO | G37: 514.24 | I37: 514.24 | J37: 18/10/2024 | K37: MO | L37: CEF 013 0892 00113057-1 - CPF: 87.942.119.6-53 | N37: =IF(ISERROR(SEARCH("NF",E37,1)),"NÃO","SIM") | O37: =IF($B37=5,"SIM","") | P37: =A37&B37&C37&E37&G37&EDATE(J37,0) | Q37: =IF(A37=0,"",VLOOKUP($A37,RESUMO!$A$8:$B$83,2,FALSE))
A38: 45585 | B38: 1 | C38: 75746980315 | D38: FRANCISCO REGO DA SILVA | E38: SALÁRIO | G38: 732.8 | I38: 732.8 | J38: 18/10/2024 | K38: MO | L38: PIX: 75746980315 | N38: =IF(ISERROR(SEARCH("NF",E38,1)),"NÃO","SIM") | O38: =IF($B38=5,"SIM","") | P38: =A38&B38&C38&E38&G38&EDATE(J38,0) | Q38: =IF(A38=0,"",VLOOKUP($A38,RESUMO!$A$8:$B$83,2,FALSE))
A39: 45585 | B39: 1 | C39: 07573876670 | D39: BRUNO JUNIO DA SILVA | E39: DIÁRIA | G39: 365 | H39: 6 | I39: 2190 | J39: 18/10/2024 | K39: MO | L39: PIX: 07573876670 | N39: =IF(ISERROR(SEARCH("NF",E39,1)),"NÃO","SIM") | O39: =IF($B39=5,"SIM","") | P39: =A39&B39&C39&E39&G39&EDATE(J39,0) | Q39: =IF(A39=0,"",VLOOKUP($A39,RESUMO!$A$8:$B$83,2,FALSE))
A40: 45585 | B40: 1 | C40: 14758063613 | D40: IZAEL BISPO OLIVEIRA | E40: DIÁRIA | G40: 215 | H40: 5 | I40: 1075 | J40: 18/10/2024 | K40: MO | L40: PIX: 14758063613 | N40: =IF(ISERROR(SEARCH("NF",E40,1)),"NÃO","SIM") | O40: =IF($B40=5,"SIM","") | P40: =A40&B40&C40&E40&G40&EDATE(J40,0) | Q40: =IF(A40=0,"",VLOOKUP($A40,RESUMO!$A$8:$B$83,2,FALSE))
...

Sheet RESUMO
G1: Rua Zodiaco, 87 Sala 07 – Santa Lúcia - Belo Horizonte - MG (31) 3654-6616 / (31) 99974-1241 / (31) 98711-1139 rvr.engenharia@gmail.com / vinicius.rinaldi26@gmail.com
A3: CLEVER LUIZ SALVADOR | K3: Data Inicial: | L3: 45540
A4: RUA MARES DE MONTANHAS, 465 - CONDOMINIO VALE DOS CRISTAIS | K4: % Adm Obra: | L4: 0.13
A6: RESUMO DAS DESPESAS | N6: % ADM OBRA
C7: 1 | D7: 2 | E7: 3 | F7: 4 | G7: 5 | H7: 6
A8: DATA | B8: Nº REL. | C8: 1) DESPESAS COM COLABORADORES | D8: 2) TRANSF. PROGR. - MATERIAIS, LOCAÇÕES E PREST. SERVIÇOS | E8: 3) MATERIAIS, PREST DE SERVIÇOS, IMPOSTOS E OUTROS | F8: 4) RESSARCIMENTOS E RESTITUIÇÕES | G8: 5) DESPESAS PAGAS PELO CLIENTE | H8: 6) PAGAMENTOS CAIXA DE OBRA | I8: SUBTOTAL | J8: 7) ADM. OBRA | K8: TOTAL | L8: ACUMULADO
A9: 45540 | B9: 1 | C9: =SUMIFS(Dados!$I$1:$I$1910,Dados!$B$1:$B$1910,C$7,Dados!$A$1:$A$1910,$A9) | D9: =SUMIFS(Dados!$I$1:$I$1910,Dados!$B$1:$B$1910,D$7,Dados!$A$1:$A$1910,$A9) | E9: =SUMIFS(Dados!$I$1:$I$1910,Dados!$B$1:$B$1910,E$7,Dados!$A$1:$A$1910,$A9) | F9: =SUMIFS(Dados!$I$1:$I$1910,Dados!$B$1:$B$1910,F$7,Dados!$A$1:$A$1910,$A9) | G9: =SUMIFS(Dados!$I$1:$I$1910,Dados!$B$1:$B$1910,G$7,Dados!$A$1:$A$1910,$A9) | H9: =SUMIFS(Dados!$I$1:$I$1910,Dados!$B$1:$B$1910,H$7,Dados!$A$1:$A$1910,$A9) | I9: =SUM(C9:H9) | J9: =ROUND(I9*$L$4,2) | K9: =SUM(I9:J9) | L9: =K9
A10: 45555 | B10: =B9+1 | C10: =SUMIFS(Dados!$I$1:$I$1910,Dados!$B$1:$B$1910,C$7,Dados!$A$1:$A$1910,$A10) | D10: =SUMIFS(Dados!$I$1:$I$1910,Dados!$B$1:$B$1910,D$7,Dados!$A$1:$A$1910,$A10) | E10: =SUMIFS(Dados!$I$1:$I$1910,Dados!$B$1:$B$1910,E$7,Dados!$A$1:$A$1910,$A10) | F10: =SUMIFS(Dados!$I$1:$I$1910,Dados!$B$1:$B$1910,F$7,Dados!$A$1:$A$1910,$A10) | G10: =SUMIFS(Dados!$I$1:$I$1910,Dados!$B$1:$B$1910,G$7,Dados!$A$1:$A$1910,$A10) | H10: =SUMIFS(Dados!$I$1:$I$1910,Dados!$B$1:$B$1910,H$7,Dados!$A$1:$A$1910,$A10) | I10: =SUM(C10:H10) | J10: =ROUND(I10*$L$4,2) | K10: =SUM(I10:J10) | L10: =ROUND(K10+L9,2)
A11: 45570 | B11: =B10+1 | C11: =SUMIFS(Dados!$I$1:$I$1910,Dados!$B$1:$B$1910,C$7,Dados!$A$1:$A$1910,$A11) | D11: =SUMIFS(Dados!$I$1:$I$1910,Dados!$B$1:$B$1910,D$7,Dados!$A$1:$A$1910,$A11) | E11: =SUMIFS(Dados!$I$1:$I$1910,Dados!$B$1:$B$1910,E$7,Dados!$A$1:$A$1910,$A11) | F11: =SUMIFS(Dados!$I$1:$I$1910,Dados!$B$1:$B$1910,F$7,Dados!$A$1:$A$1910,$A11) | G11: =SUMIFS(Dados!$I$1:$I$1910,Dados!$B$1:$B$1910,G$7,Dados!$A$1:$A$1910,$A11) | H11: =SUMIFS(Dados!$I$1:$I$1910,Dados!$B$1:$B$1910,H$7,Dados!$A$1:$A$1910,$A11) | I11: =SUM(C11:H11) | J11: =ROUND(I11*$L$4,2) | K11: =SUM(I11:J11) | L11: =ROUND(K11+L10,2)
A12: 45585 | B12: =B11+1 | C12: =SUMIFS(Dados!$I$1:$I$1910,Dados!$B$1:$B$1910,C$7,Dados!$A$1:$A$1910,$A12) | D12: =SUMIFS(Dados!$I$1:$I$1910,Dados!$B$1:$B$1910,D$7,Dados!$A$1:$A$1910,$A12) | E12: =SUMIFS(Dados!$I$1:$I$1910,Dados!$B$1:$B$1910,E$7,Dados!$A$1:$A$1910,$A12) | F12: =SUMIFS(Dados!$I$1:$I$1910,Dados!$B$1:$B$1910,F$7,Dados!$A$1:$A$1910,$A12) | G12: =SUMIFS(Dados!$I$1:$I$1910,Dados!$B$1:$B$1910,G$7,Dados!$A$1:$A$1910,$A12) | H12: =SUMIFS(Dados!$I$1:$I$1910,Dados!$B$1:$B$1910,H$7,Dados!$A$1:$A$1910,$A12) | I12: =SUM(C12:H12) | J12: =ROUND(I12*$L$4,2) | K12: =SUM(I12:J12) | L12: =ROUND(K12+L11,2)
A13: 45601 | B13: =B12+1 | C13: =SUMIFS(Dados!$I$1:$I$1910,Dados!$B$1:$B$1910,C$7,Dados!$A$1:$A$1910,$A13) | D13: =SUMIFS(Dados!$I$1:$I$1910,Dados!$B$1:$B$1910,D$7,Dados!$A$1:$A$1910,$A13) | E13: =SUMIFS(Dados!$I$1:$I$1910,Dados!$B$1:$B$1910,E$7,Dados!$A$1:$A$1910,$A13) | F13: =SUMIFS(Dados!$I$1:$I$1910,Dados!$B$1:$B$1910,F$7,Dados!$A$1:$A$1910,$A13) | G13: =SUMIFS(Dados!$I$1:$I$1910,Dados!$B$1:$B$1910,G$7,Dados!$A$1:$A$1910,$A13) | H13: =SUMIFS(Dados!$I$1:$I$1910,Dados!$B$1:$B$1910,H$7,Dados!$A$1:$A$1910,$A13) | I13: =SUM(C13:H13) | J13: =ROUND(I13*$L$4,2) | K13: =SUM(I13:J13) | L13: =ROUND(K13+L12,2)
A14: 45616 | B14: =B13+1 | C14: =SUMIFS(Dados!$I$1:$I$1910,Dados!$B$1:$B$1910,C$7,Dados!$A$1:$A$1910,$A14) | D14: =SUMIFS(Dados!$I$1:$I$1910,Dados!$B$1:$B$1910,D$7,Dados!$A$1:$A$1910,$A14) | E14: =SUMIFS(Dados!$I$1:$I$1910,Dados!$B$1:$B$1910,E$7,Dados!$A$1:$A$1910,$A14) | F14: =SUMIFS(Dados!$I$1:$I$1910,Dados!$B$1:$B$1910,F$7,Dados!$A$1:$A$1910,$A14) | G14: =SUMIFS(Dados!$I$1:$I$1910,Dados!$B$1:$B$1910,G$7,Dados!$A$1:$A$1910,$A14) | H14: =SUMIFS(Dados!$I$1:$I$1910,Dados!$B$1:$B$1910,H$7,Dados!$A$1:$A$1910,$A14) | I14: =SUM(C14:H14) | J14: =ROUND(I14*$L$4,2) | K14: =SUM(I14:J14) | L14: =ROUND(K14+L13,2)
A15: 45631 | B15: =B14+1 | C15: =SUMIFS(Dados!$I$1:$I$1910,Dados!$B$1:$B$1910,C$7,Dados!$A$1:$A$1910,$A15) | D15: =SUMIFS(Dados!$I$1:$I$1910,Dados!$B$1:$B$1910,D$7,Dados!$A$1:$A$1910,$A15) | E15: =SUMIFS(Dados!$I$1:$I$1910,Dados!$B$1:$B$1910,E$7,Dados!$A$1:$A$1910,$A15) | F15: =SUMIFS(Dados!$I$1:$I$1910,Dados!$B$1:$B$1910,F$7,Dados!$A$1:$A$1910,$A15) | G15: =SUMIFS(Dados!$I$1:$I$1910,Dados!$B$1:$B$1910,G$7,Dados!$A$1:$A$1910,$A15) | H15: =SUMIFS(Dados!$I$1:$I$1910,Dados!$B$1:$B$1910,H$7,Dados!$A$1:$A$1910,$A15) | I15: =SUM(C15:H15) | J15: =ROUND(I15*$L$4,2) | K15: =SUM(I15:J15) | L15: =ROUND(K15+L14,2)
A16: 45646 | B16: =B15+1 | C16: =SUMIFS(Dados!$I$1:$I$1910,Dados!$B$1:$B$1910,C$7,Dados!$A$1:$A$1910,$A16) | D16: =SUMIFS(Dados!$I$1:$I$1910,Dados!$B$1:$B$1910,D$7,Dados!$A$1:$A$1910,$A16) | E16: =SUMIFS(Dados!$I$1:$I$1910,Dados!$B$1:$B$1910,E$7,Dados!$A$1:$A$1910,$A16) | F16: =SUMIFS(Dados!$I$1:$I$1910,Dados!$B$1:$B$1910,F$7,Dados!$A$1:$A$1910,$A16) | G16: =SUMIFS(Dados!$I$1:$I$1910,Dados!$B$1:$B$1910,G$7,Dados!$A$1:$A$1910,$A16) | H16: =SUMIFS(Dados!$I$1:$I$1910,Dados!$B$1:$B$1910,H$7,Dados!$A$1:$A$1910,$A16) | I16: =SUM(C16:H16) | J16: =ROUND(I16*$L$4,2) | K16: =SUM(I16:J16) | L16: =ROUND(K16+L15,2)
A17: 45662 | B17: =B16+1 | C17: =SUMIFS(Dados!$I$1:$I$1910,Dados!$B$1:$B$1910,C$7,Dados!$A$1:$A$1910,$A17) | D17: =SUMIFS(Dados!$I$1:$I$1910,Dados!$B$1:$B$1910,D$7,Dados!$A$1:$A$1910,$A17) | E17: =SUMIFS(Dados!$I$1:$I$1910,Dados!$B$1:$B$1910,E$7,Dados!$A$1:$A$1910,$A17) | F17: =SUMIFS(Dados!$I$1:$I$1910,Dados!$B$1:$B$1910,F$7,Dados!$A$1:$A$1910,$A17) | G17: =SUMIFS(Dados!$I$1:$I$1910,Dados!$B$1:$B$1910,G$7,Dados!$A$1:$A$1910,$A17) | H17: =SUMIFS(Dados!$I$1:$I$1910,Dados!$B$1:$B$1910,H$7,Dados!$A$1:$A$1910,$A17) | I17: =SUM(C17:H17) | J17: =ROUND(I17*$L$4,2) | K17: =SUM(I17:J17) | L17: =ROUND(K17+L16,2)
A18: 45677 | B18: =B17+1 | C18: =SUMIFS(Dados!$I$1:$I$1910,Dados!$B$1:$B$1910,C$7,Dados!$A$1:$A$1910,$A18) | D18: =SUMIFS(Dados!$I$1:$I$1910,Dados!$B$1:$B$1910,D$7,Dados!$A$1:$A$1910,$A18) | E18: =SUMIFS(Dados!$I$1:$I$1910,Dados!$B$1:$B$1910,E$7,Dados!$A$1:$A$1910,$A18) | F18: =SUMIFS(Dados!$I$1:$I$1910,Dados!$B$1:$B$1910,F$7,Dados!$A$1:$A$1910,$A18) | G18: =SUMIFS(Dados!$I$1:$I$1910,Dados!$B$1:$B$1910,G$7,Dados!$A$1:$A$1910,$A18) | H18: =SUMIFS(Dados!$I$1:$I$1910,Dados!$B$1:$B$1910,H$7,Dados!$A$1:$A$1910,$A18) | I18: =SUM(C18:H18) | J18: =ROUND(I18*$L$4,2) | K18: =SUM(I18:J18) | L18: =ROUND(K18+L17,2)
A19: 45693 | B19: =B18+1 | C19: =SUMIFS(Dados!$I$1:$I$1910,Dados!$B$1:$B$1910,C$7,Dados!$A$1:$A$1910,$A19) | D19: =SUMIFS(Dados!$I$1:$I$1910,Dados!$B$1:$B$1910,D$7,Dados!$A$1:$A$1910,$A19) | E19: =SUMIFS(Dados!$I$1:$I$1910,Dados!$B$1:$B$1910,E$7,Dados!$A$1:$A$1910,$A19) | F19: =SUMIFS(Dados!$I$1:$I$1910,Dados!$B$1:$B$1910,F$7,Dados!$A$1:$A$1910,$A19) | G19: =SUMIFS(Dados!$I$1:$I$1910,Dados!$B$1:$B$1910,G$7,Dados!$A$1:$A$1910,$A19) | H19: =SUMIFS(Dados!$I$1:$I$1910,Dados!$B$1:$B$1910,H$7,Dados!$A$1:$A$1910,$A19) | I19: =SUM(C19:H19) | J19: =ROUND(I19*$L$4,2) | K19: =SUM(I19:J19) | L19: =ROUND(K19+L18,2)
A20: 45708 | B20: =B19+1 | C20: =SUMIFS(Dados!$I$1:$I$1910,Dados!$B$1:$B$1910,C$7,Dados!$A$1:$A$1910,$A20) | D20: =SUMIFS(Dados!$I$1:$I$1910,Dados!$B$1:$B$1910,D$7,Dados!$A$1:$A$1910,$A20) | E20: =SUMIFS(Dados!$I$1:$I$1910,Dados!$B$1:$B$1910,E$7,Dados!$A$1:$A$1910,$A20) | F20: =SUMIFS(Dados!$I$1:$I$1910,Dados!$B$1:$B$1910,F$7,Dados!$A$1:$A$1910,$A20) | G20: =SUMIFS(Dados!$I$1:$I$1910,Dados!$B$1:$B$1910,G$7,Dados!$A$1:$A$1910,$A20) | H20: =SUMIFS(Dados!$I$1:$I$1910,Dados!$B$1:$B$1910,H$7,Dados!$A$1:$A$1910,$A20) | I20: =SUM(C20:H20) | J20: =ROUND(I20*$L$4,2) | K20: =SUM(I20:J20) | L20: =ROUND(K20+L19,2)
A21: 45721 | B21: =B20+1 | C21: =SUMIFS(Dados!$I$1:$I$1910,Dados!$B$1:$B$1910,C$7,Dados!$A$1:$A$1910,$A21) | D21: =SUMIFS(Dados!$I$1:$I$1910,Dados!$B$1:$B$1910,D$7,Dados!$A$1:$A$1910,$A21) | E21: =SUMIFS(Dados!$I$1:$I$1910,Dados!$B$1:$B$1910,E$7,Dados!$A$1:$A$1910,$A21) | F21: =SUMIFS(Dados!$I$1:$I$1910,Dados!$B$1:$B$1910,F$7,Dados!$A$1:$A$1910,$A21) | G21: =SUMIFS(Dados!$I$1:$I$1910,Dados!$B$1:$B$1910,G$7,Dados!$A$1:$A$1910,$A21) | H21: =SUMIFS(Dados!$I$1:$I$1910,Dados!$B$1:$B$1910,H$7,Dados!$A$1:$A$1910,$A21) | I21: =SUM(C21:H21) | J21: =ROUND(I21*$L$4,2) | K21: =SUM(I21:J21) | L21: =ROUND(K21+L20,2)
... A80: 46619 | B80: =B79+1 | C80: =SUMIFS(Dados!$I$1:$I$1910,Dados!$B$1:$B$1910,C$7,Dados!$A$1:$A$1910,$A80) | D80: =SUMIFS(Dados!$I$1:$I$1910,Dados!$B$1:$B$1910,D$7,Dados!$A$1:$A$1910,$A80) | E80: =SUMIFS(Dados!$I$1:$I$1910,Dados!$B$1:$B$1910,E$7,Dados!$A$1:$A$1910,$A80) | F80: =SUMIFS(Dados!$I$1:$I$1910,Dados!$B$1:$B$1910,F$7,Dados!$A$1:$A$1910,$A80) | G80: =SUMIFS(Dados!$I$1:$I$1910,Dados!$B$1:$B$1910,G$7,Dados!$A$1:$A$1910,$A80) | H80: =SUMIFS(Dados!$I$1:$I$1910,Dados!$B$1:$B$1910,H$7,Dados!$A$1:$A$1910,$A80) | I80: =SUM(C80:H80) | J80: =ROUND(I80*$L$4,2) | K80: =SUM(I80:J80) | L80: =ROUND(K80+L79,2)
A81: TOTAL | C81: =SUM(C9:C80) | D81: =SUM(D9:D80) | E81: =SUM(E9:E80) | F81: =SUM(F9:F80) | G81: =SUM(G9:G80) | H81: =SUM(H9:H80) | I81: =SUM(I9:I80) | J81: =SUM(J9:J80) | K81: =SUM(K9:K80)

Sheet Tp.Despesas
G1: Rua Zodiaco, 87 Sala 07 – Santa Lúcia - Belo Horizonte - MG (31) 3654-6616 / (31) 99974-1241 / (31) 98711-1139 rvr.engenharia@gmail.com / vinicius.rinaldi26@gmail.com
A3: =RESUMO!A3
A4: =RESUMO!A4
A6: RESUMO POR TIPO DE DESPESAS
C7: ADM | D7: DIV | E7: LOC | F7: MAT | G7: MO | H7: SERV | I7: TP
A8: DATA | C8: ADMINISTRATIVO | D8: DIVERSOS | E8: LOCAÇAO | F8: MATERIAL | G8: MÃO DE OBRA | H8: SERVIÇOS | I8: TARIFAS/TRIBUTOS PÚBLICAS | J8: TOTAL
A9: =DATE(YEAR(RESUMO!A9),MONTH(RESUMO!A9),1) | C9: =SUMIFS(Dados!$I$1:$I$1919,Dados!$K$1:$K$1919,Tp.Despesas!C$7,Dados!$A$1:$A$1919,">="&$A9,Dados!$A$1:$A$1919,"<="&EOMONTH($A9,0)) | D9: =SUMIFS(Dados!$I$1:$I$1919,Dados!$K$1:$K$1919,Tp.Despesas!D$7,Dados!$A$1:$A$1919,">="&$A9,Dados!$A$1:$A$1919,"<="&EOMONTH($A9,0)) | E9: =SUMIFS(Dados!$I$1:$I$1919,Dados!$K$1:$K$1919,Tp.Despesas!E$7,Dados!$A$1:$A$1919,">="&$A9,Dados!$A$1:$A$1919,"<="&EOMONTH($A9,0)) | F9: =SUMIFS(Dados!$I$1:$I$1919,Dados!$K$1:$K$1919,Tp.Despesas!F$7,Dados!$A$1:$A$1919,">="&$A9,Dados!$A$1:$A$1919,"<="&EOMONTH($A9,0)) | G9: =SUMIFS(Dados!$I$1:$I$1919,Dados!$K$1:$K$1919,Tp.Despesas!G$7,Dados!$A$1:$A$1919,">="&$A9,Dados!$A$1:$A$1919,"<="&EOMONTH($A9,0)) | H9: =SUMIFS(Dados!$I$1:$I$1919,Dados!$K$1:$K$1919,Tp.Despesas!H$7,Dados!$A$1:$A$1919,">="&$A9,Dados!$A$1:$A$1919,"<="&EOMONTH($A9,0)) | I9: =SUMIFS(Dados!$I$1:$I$1919,Dados!$K$1:$K$1919,Tp.Despesas!I$7,Dados!$A$1:$A$1919,">="&$A9,Dados!$A$1:$A$1919,"<="&EOMONTH($A9,0)) | J9: =SUM(C9:I9)
A10: =EOMONTH(A9,1)-DAY(EOMONTH(A9,1))+1 | C10: =SUMIFS(Dados!$I$1:$I$1919,Dados!$K$1:$K$1919,Tp.Despesas!C$7,Dados!$A$1:$A$1919,">="&$A10,Dados!$A$1:$A$1919,"<="&EOMONTH($A10,0)) | D10: =SUMIFS(Dados!$I$1:$I$1919,Dados!$K$1:$K$1919,Tp.Despesas!D$7,Dados!$A$1:$A$1919,">="&$A10,Dados!$A$1:$A$1919,"<="&EOMONTH($A10,0)) | E10: =SUMIFS(Dados!$I$1:$I$1919,Dados!$K$1:$K$1919,Tp.Despesas!E$7,Dados!$A$1:$A$1919,">="&$A10,Dados!$A$1:$A$1919,"<="&EOMONTH($A10,0)) | F10: =SUMIFS(Dados!$I$1:$I$1919,Dados!$K$1:$K$1919,Tp.Despesas!F$7,Dados!$A$1:$A$1919,">="&$A10,Dados!$A$1:$A$1919,"<="&EOMONTH($A10,0)) | G10: =SUMIFS(Dados!$I$1:$I$1919,Dados!$K$1:$K$1919,Tp.Despesas!G$7,Dados!$A$1:$A$1919,">="&$A10,Dados!$A$1:$A$1919,"<="&EOMONTH($A10,0)) | H10: =SUMIFS(Dados!$I$1:$I$1919,Dados!$K$1:$K$1919,Tp.Despesas!H$7,Dados!$A$1:$A$1919,">="&$A10,Dados!$A$1:$A$1919,"<="&EOMONTH($A10,0)) | I10: =SUMIFS(Dados!$I$1:$I$1919,Dados!$K$1:$K$1919,Tp.Despesas!I$7,Dados!$A$1:$A$1919,">="&$A10,Dados!$A$1:$A$1919,"<="&EOMONTH($A10,0)) | J10: =SUM(C10:I10)
A11: =EOMONTH(A10,1)-DAY(EOMONTH(A10,1))+1 | C11: =SUMIFS(Dados!$I$1:$I$1919,Dados!$K$1:$K$1919,Tp.Despesas!C$7,Dados!$A$1:$A$1919,">="&$A11,Dados!$A$1:$A$1919,"<="&EOMONTH($A11,0)) | D11: =SUMIFS(Dados!$I$1:$I$1919,Dados!$K$1:$K$1919,Tp.Despesas!D$7,Dados!$A$1:$A$1919,">="&$A11,Dados!$A$1:$A$1919,"<="&EOMONTH($A11,0)) | E11: =SUMIFS(Dados!$I$1:$I$1919,Dados!$K$1:$K$1919,Tp.Despesas!E$7,Dados!$A$1:$A$1919,">="&$A11,Dados!$A$1:$A$1919,"<="&EOMONTH($A11,0)) | F11: =SUMIFS(Dados!$I$1:$I$1919,Dados!$K$1:$K$1919,Tp.Despesas!F$7,Dados!$A$1:$A$1919,">="&$A11,Dados!$A$1:$A$1919,"<="&EOMONTH($A11,0)) | G11: =SUMIFS(Dados!$I$1:$I$1919,Dados!$K$1:$K$1919,Tp.Despesas!G$7,Dados!$A$1:$A$1919,">="&$A11,Dados!$A$1:$A$1919,"<="&EOMONTH($A11,0)) | H11: =SUMIFS(Dados!$I$1:$I$1919,Dados!$K$1:$K$1919,Tp.Despesas!H$7,Dados!$A$1:$A$1919,">="&$A11,Dados!$A$1:$A$1919,"<="&EOMONTH($A11,0)) | I11: =SUMIFS(Dados!$I$1:$I$1919,Dados!$K$1:$K$1919,Tp.Despesas!I$7,Dados!$A$1:$A$1919,">="&$A11,Dados!$A$1:$A$1919,"<="&EOMONTH($A11,0)) | J11: =SUM(C11:I11)
A12: =EOMONTH(A11,1)-DAY(EOMONTH(A11,1))+1 | C12: =SUMIFS(Dados!$I$1:$I$1919,Dados!$K$1:$K$1919,Tp.Despesas!C$7,Dados!$A$1:$A$1919,">="&$A12,Dados!$A$1:$A$1919,"<="&EOMONTH($A12,0)) | D12: =SUMIFS(Dados!$I$1:$I$1919,Dados!$K$1:$K$1919,Tp.Despesas!D$7,Dados!$A$1:$A$1919,">="&$A12,Dados!$A$1:$A$1919,"<="&EOMONTH($A12,0)) | E12: =SUMIFS(Dados!$I$1:$I$1919,Dados!$K$1:$K$1919,Tp.Despesas!E$7,Dados!$A$1:$A$1919,">="&$A12,Dados!$A$1:$A$1919,"<="&EOMONTH($A12,0)) | F12: =SUMIFS(Dados!$I$1:$I$1919,Dados!$K$1:$K$1919,Tp.Despesas!F$7,Dados!$A$1:$A$1919,">="&$A12,Dados!$A$1:$A$1919,"<="&EOMONTH($A12,0)) | G12: =SUMIFS(Dados!$I$1:$I$1919,Dados!$K$1:$K$1919,Tp.Despesas!G$7,Dados!$A$1:$A$1919,">="&$A12,Dados!$A$1:$A$1919,"<="&EOMONTH($A12,0)) | H12: =SUMIFS(Dados!$I$1:$I$1919,Dados!$K$1:$K$1919,Tp.Despesas!H$7,Dados!$A$1:$A$1919,">="&$A12,Dados!$A$1:$A$1919,"<="&EOMONTH($A12,0)) | I12: =SUMIFS(Dados!$I$1:$I$1919,Dados!$K$1:$K$1919,Tp.Despesas!I$7,Dados!$A$1:$A$1919,">="&$A12,Dados!$A$1:$A$1919,"<="&EOMONTH($A12,0)) | J12: =SUM(C12:I12)
A13: =EOMONTH(A12,1)-DAY(EOMONTH(A12,1))+1 | C13: =SUMIFS(Dados!$I$1:$I$1919,Dados!$K$1:$K$1919,Tp.Despesas!C$7,Dados!$A$1:$A$1919,">="&$A13,Dados!$A$1:$A$1919,"<="&EOMONTH($A13,0)) | D13: =SUMIFS(Dados!$I$1:$I$1919,Dados!$K$1:$K$1919,Tp.Despesas!D$7,Dados!$A$1:$A$1919,">="&$A13,Dados!$A$1:$A$1919,"<="&EOMONTH($A13,0)) | E13: =SUMIFS(Dados!$I$1:$I$1919,Dados!$K$1:$K$1919,Tp.Despesas!E$7,Dados!$A$1:$A$1919,">="&$A13,Dados!$A$1:$A$1919,"<="&EOMONTH($A13,0)) | F13: =SUMIFS(Dados!$I$1:$I$1919,Dados!$K$1:$K$1919,Tp.Despesas!F$7,Dados!$A$1:$A$1919,">="&$A13,Dados!$A$1:$A$1919,"<="&EOMONTH($A13,0)) | G13: =SUMIFS(Dados!$I$1:$I$1919,Dados!$K$1:$K$1919,Tp.Despesas!G$7,Dados!$A$1:$A$1919,">="&$A13,Dados!$A$1:$A$1919,"<="&EOMONTH($A13,0)) | H13: =SUMIFS(Dados!$I$1:$I$1919,Dados!$K$1:$K$1919,Tp.Despesas!H$7,Dados!$A$1:$A$1919,">="&$A13,Dados!$A$1:$A$1919,"<="&EOMONTH($A13,0)) | I13: =SUMIFS(Dados!$I$1:$I$1919,Dados!$K$1:$K$1919,Tp.Despesas!I$7,Dados!$A$1:$A$1919,">="&$A13,Dados!$A$1:$A$1919,"<="&EOMONTH($A13,0)) | J13: =SUM(C13:I13)
A14: =EOMONTH(A13,1)-DAY(EOMONTH(A13,1))+1 | C14: =SUMIFS(Dados!$I$1:$I$1919,Dados!$K$1:$K$1919,Tp.Despesas!C$7,Dados!$A$1:$A$1919,">="&$A14,Dados!$A$1:$A$1919,"<="&EOMONTH($A14,0)) | D14: =SUMIFS(Dados!$I$1:$I$1919,Dados!$K$1:$K$1919,Tp.Despesas!D$7,Dados!$A$1:$A$1919,">="&$A14,Dados!$A$1:$A$1919,"<="&EOMONTH($A14,0)) | E14: =SUMIFS(Dados!$I$1:$I$1919,Dados!$K$1:$K$1919,Tp.Despesas!E$7,Dados!$A$1:$A$1919,">="&$A14,Dados!$A$1:$A$1919,"<="&EOMONTH($A14,0)) | F14: =SUMIFS(Dados!$I$1:$I$1919,Dados!$K$1:$K$1919,Tp.Despesas!F$7,Dados!$A$1:$A$1919,">="&$A14,Dados!$A$1:$A$1919,"<="&EOMONTH($A14,0)) | G14: =SUMIFS(Dados!$I$1:$I$1919,Dados!$K$1:$K$1919,Tp.Despesas!G$7,Dados!$A$1:$A$1919,">="&$A14,Dados!$A$1:$A$1919,"<="&EOMONTH($A14,0)) | H14: =SUMIFS(Dados!$I$1:$I$1919,Dados!$K$1:$K$1919,Tp.Despesas!H$7,Dados!$A$1:$A$1919,">="&$A14,Dados!$A$1:$A$1919,"<="&EOMONTH($A14,0)) | I14: =SUMIFS(Dados!$I$1:$I$1919,Dados!$K$1:$K$1919,Tp.Despesas!I$7,Dados!$A$1:$A$1919,">="&$A14,Dados!$A$1:$A$1919,"<="&EOMONTH($A14,0)) | J14: =SUM(C14:I14)
A15: =EOMONTH(A14,1)-DAY(EOMONTH(A14,1))+1 | C15: =SUMIFS(Dados!$I$1:$I$1919,Dados!$K$1:$K$1919,Tp.Despesas!C$7,Dados!$A$1:$A$1919,">="&$A15,Dados!$A$1:$A$1919,"<="&EOMONTH($A15,0)) | D15: =SUMIFS(Dados!$I$1:$I$1919,Dados!$K$1:$K$1919,Tp.Despesas!D$7,Dados!$A$1:$A$1919,">="&$A15,Dados!$A$1:$A$1919,"<="&EOMONTH($A15,0)) | E15: =SUMIFS(Dados!$I$1:$I$1919,Dados!$K$1:$K$1919,Tp.Despesas!E$7,Dados!$A$1:$A$1919,">="&$A15,Dados!$A$1:$A$1919,"<="&EOMONTH($A15,0)) | F15: =SUMIFS(Dados!$I$1:$I$1919,Dados!$K$1:$K$1919,Tp.Despesas!F$7,Dados!$A$1:$A$1919,">="&$A15,Dados!$A$1:$A$1919,"<="&EOMONTH($A15,0)) | G15: =SUMIFS(Dados!$I$1:$I$1919,Dados!$K$1:$K$1919,Tp.Despesas!G$7,Dados!$A$1:$A$1919,">="&$A15,Dados!$A$1:$A$1919,"<="&EOMONTH($A15,0)) | H15: =SUMIFS(Dados!$I$1:$I$1919,Dados!$K$1:$K$1919,Tp.Despesas!H$7,Dados!$A$1:$A$1919,">="&$A15,Dados!$A$1:$A$1919,"<="&EOMONTH($A15,0)) | I15: =SUMIFS(Dados!$I$1:$I$1919,Dados!$K$1:$K$1919,Tp.Despesas!I$7,Dados!$A$1:$A$1919,">="&$A15,Dados!$A$1:$A$1919,"<="&EOMONTH($A15,0)) | J15: =SUM(C15:I15)
A16: =EOMONTH(A15,1)-DAY(EOMONTH(A15,1))+1 | C16: =SUMIFS(Dados!$I$1:$I$1919,Dados!$K$1:$K$1919,Tp.Despesas!C$7,Dados!$A$1:$A$1919,">="&$A16,Dados!$A$1:$A$1919,"<="&EOMONTH($A16,0)) | D16: =SUMIFS(Dados!$I$1:$I$1919,Dados!$K$1:$K$1919,Tp.Despesas!D$7,Dados!$A$1:$A$1919,">="&$A16,Dados!$A$1:$A$1919,"<="&EOMONTH($A16,0)) | E16: =SUMIFS(Dados!$I$1:$I$1919,Dados!$K$1:$K$1919,Tp.Despesas!E$7,Dados!$A$1:$A$1919,">="&$A16,Dados!$A$1:$A$1919,"<="&EOMONTH($A16,0)) | F16: =SUMIFS(Dados!$I$1:$I$1919,Dados!$K$1:$K$1919,Tp.Despesas!F$7,Dados!$A$1:$A$1919,">="&$A16,Dados!$A$1:$A$1919,"<="&EOMONTH($A16,0)) | G16: =SUMIFS(Dados!$I$1:$I$1919,Dados!$K$1:$K$1919,Tp.Despesas!G$7,Dados!$A$1:$A$1919,">="&$A16,Dados!$A$1:$A$1919,"<="&EOMONTH($A16,0)) | H16: =SUMIFS(Dados!$I$1:$I$1919,Dados!$K$1:$K$1919,Tp.Despesas!H$7,Dados!$A$1:$A$1919,">="&$A16,Dados!$A$1:$A$1919,"<="&EOMONTH($A16,0)) | I16: =SUMIFS(Dados!$I$1:$I$1919,Dados!$K$1:$K$1919,Tp.Despesas!I$7,Dados!$A$1:$A$1919,">="&$A16,Dados!$A$1:$A$1919,"<="&EOMONTH($A16,0)) | J16: =SUM(C16:I16)
A17: =EOMONTH(A16,1)-DAY(EOMONTH(A16,1))+1 | C17: =SUMIFS(Dados!$I$1:$I$1919,Dados!$K$1:$K$1919,Tp.Despesas!C$7,Dados!$A$1:$A$1919,">="&$A17,Dados!$A$1:$A$1919,"<="&EOMONTH($A17,0)) | D17: =SUMIFS(Dados!$I$1:$I$1919,Dados!$K$1:$K$1919,Tp.Despesas!D$7,Dados!$A$1:$A$1919,">="&$A17,Dados!$A$1:$A$1919,"<="&EOMONTH($A17,0)) | E17: =SUMIFS(Dados!$I$1:$I$1919,Dados!$K$1:$K$1919,Tp.Despesas!E$7,Dados!$A$1:$A$1919,">="&$A17,Dados!$A$1:$A$1919,"<="&EOMONTH($A17,0)) | F17: =SUMIFS(Dados!$I$1:$I$1919,Dados!$K$1:$K$1919,Tp.Despesas!F$7,Dados!$A$1:$A$1919,">="&$A17,Dados!$A$1:$A$1919,"<="&EOMONTH($A17,0)) | G17: =SUMIFS(Dados!$I$1:$I$1919,Dados!$K$1:$K$1919,Tp.Despesas!G$7,Dados!$A$1:$A$1919,">="&$A17,Dados!$A$1:$A$1919,"<="&EOMONTH($A17,0)) | H17: =SUMIFS(Dados!$I$1:$I$1919,Dados!$K$1:$K$1919,Tp.Despesas!H$7,Dados!$A$1:$A$1919,">="&$A17,Dados!$A$1:$A$1919,"<="&EOMONTH($A17,0)) | I17: =SUMIFS(Dados!$I$1:$I$1919,Dados!$K$1:$K$1919,Tp.Despesas!I$7,Dados!$A$1:$A$1919,">="&$A17,Dados!$A$1:$A$1919,"<="&EOMONTH($A17,0)) | J17: =SUM(C17:I17)
A18: =EOMONTH(A17,1)-DAY(EOMONTH(A17,1))+1 | C18: =SUMIFS(Dados!$I$1:$I$1919,Dados!$K$1:$K$1919,Tp.Despesas!C$7,Dados!$A$1:$A$1919,">="&$A18,Dados!$A$1:$A$1919,"<="&EOMONTH($A18,0)) | D18: =SUMIFS(Dados!$I$1:$I$1919,Dados!$K$1:$K$1919,Tp.Despesas!D$7,Dados!$A$1:$A$1919,">="&$A18,Dados!$A$1:$A$1919,"<="&EOMONTH($A18,0)) | E18: =SUMIFS(Dados!$I$1:$I$1919,Dados!$K$1:$K$1919,Tp.Despesas!E$7,Dados!$A$1:$A$1919,">="&$A18,Dados!$A$1:$A$1919,"<="&EOMONTH($A18,0)) | F18: =SUMIFS(Dados!$I$1:$I$1919,Dados!$K$1:$K$1919,Tp.Despesas!F$7,Dados!$A$1:$A$1919,">="&$A18,Dados!$A$1:$A$1919,"<="&EOMONTH($A18,0)) | G18: =SUMIFS(Dados!$I$1:$I$1919,Dados!$K$1:$K$1919,Tp.Despesas!G$7,Dados!$A$1:$A$1919,">="&$A18,Dados!$A$1:$A$1919,"<="&EOMONTH($A18,0)) | H18: =SUMIFS(Dados!$I$1:$I$1919,Dados!$K$1:$K$1919,Tp.Despesas!H$7,Dados!$A$1:$A$1919,">="&$A18,Dados!$A$1:$A$1919,"<="&EOMONTH($A18,0)) | I18: =SUMIFS(Dados!$I$1:$I$1919,Dados!$K$1:$K$1919,Tp.Despesas!I$7,Dados!$A$1:$A$1919,">="&$A18,Dados!$A$1:$A$1919,"<="&EOMONTH($A18,0)) | J18: =SUM(C18:I18)
A19: =EOMONTH(A18,1)-DAY(EOMONTH(A18,1))+1 | C19: =SUMIFS(Dados!$I$1:$I$1919,Dados!$K$1:$K$1919,Tp.Despesas!C$7,Dados!$A$1:$A$1919,">="&$A19,Dados!$A$1:$A$1919,"<="&EOMONTH($A19,0)) | D19: =SUMIFS(Dados!$I$1:$I$1919,Dados!$K$1:$K$1919,Tp.Despesas!D$7,Dados!$A$1:$A$1919,">="&$A19,Dados!$A$1:$A$1919,"<="&EOMONTH($A19,0)) | E19: =SUMIFS(Dados!$I$1:$I$1919,Dados!$K$1:$K$1919,Tp.Despesas!E$7,Dados!$A$1:$A$1919,">="&$A19,Dados!$A$1:$A$1919,"<="&EOMONTH($A19,0)) | F19: =SUMIFS(Dados!$I$1:$I$1919,Dados!$K$1:$K$1919,Tp.Despesas!F$7,Dados!$A$1:$A$1919,">="&$A19,Dados!$A$1:$A$1919,"<="&EOMONTH($A19,0)) | G19: =SUMIFS(Dados!$I$1:$I$1919,Dados!$K$1:$K$1919,Tp.Despesas!G$7,Dados!$A$1:$A$1919,">="&$A19,Dados!$A$1:$A$1919,"<="&EOMONTH($A19,0)) | H19: =SUMIFS(Dados!$I$1:$I$1919,Dados!$K$1:$K$1919,Tp.Despesas!H$7,Dados!$A$1:$A$1919,">="&$A19,Dados!$A$1:$A$1919,"<="&EOMONTH($A19,0)) | I19: =SUMIFS(Dados!$I$1:$I$1919,Dados!$K$1:$K$1919,Tp.Despesas!I$7,Dados!$A$1:$A$1919,">="&$A19,Dados!$A$1:$A$1919,"<="&EOMONTH($A19,0)) | J19: =SUM(C19:I19)
A20: =EOMONTH(A19,1)-DAY(EOMONTH(A19,1))+1 | C20: =SUMIFS(Dados!$I$1:$I$1919,Dados!$K$1:$K$1919,Tp.Despesas!C$7,Dados!$A$1:$A$1919,">="&$A20,Dados!$A$1:$A$1919,"<="&EOMONTH($A20,0)) | D20: =SUMIFS(Dados!$I$1:$I$1919,Dados!$K$1:$K$1919,Tp.Despesas!D$7,Dados!$A$1:$A$1919,">="&$A20,Dados!$A$1:$A$1919,"<="&EOMONTH($A20,0)) | E20: =SUMIFS(Dados!$I$1:$I$1919,Dados!$K$1:$K$1919,Tp.Despesas!E$7,Dados!$A$1:$A$1919,">="&$A20,Dados!$A$1:$A$1919,"<="&EOMONTH($A20,0)) | F20: =SUMIFS(Dados!$I$1:$I$1919,Dados!$K$1:$K$1919,Tp.Despesas!F$7,Dados!$A$1:$A$1919,">="&$A20,Dados!$A$1:$A$1919,"<="&EOMONTH($A20,0)) | G20: =SUMIFS(Dados!$I$1:$I$1919,Dados!$K$1:$K$1919,Tp.Despesas!G$7,Dados!$A$1:$A$1919,">="&$A20,Dados!$A$1:$A$1919,"<="&EOMONTH($A20,0)) | H20: =SUMIFS(Dados!$I$1:$I$1919,Dados!$K$1:$K$1919,Tp.Despesas!H$7,Dados!$A$1:$A$1919,">="&$A20,Dados!$A$1:$A$1919,"<="&EOMONTH($A20,0)) | I20: =SUMIFS(Dados!$I$1:$I$1919,Dados!$K$1:$K$1919,Tp.Despesas!I$7,Dados!$A$1:$A$1919,">="&$A20,Dados!$A$1:$A$1919,"<="&EOMONTH($A20,0)) | J20: =SUM(C20:I20)
A21: =EOMONTH(A20,1)-DAY(EOMONTH(A20,1))+1 | C21: =SUMIFS(Dados!$I$1:$I$1919,Dados!$K$1:$K$1919,Tp.Despesas!C$7,Dados!$A$1:$A$1919,">="&$A21,Dados!$A$1:$A$1919,"<="&EOMONTH($A21,0)) | D21: =SUMIFS(Dados!$I$1:$I$1919,Dados!$K$1:$K$1919,Tp.Despesas!D$7,Dados!$A$1:$A$1919,">="&$A21,Dados!$A$1:$A$1919,"<="&EOMONTH($A21,0)) | E21: =SUMIFS(Dados!$I$1:$I$1919,Dados!$K$1:$K$1919,Tp.Despesas!E$7,Dados!$A$1:$A$1919,">="&$A21,Dados!$A$1:$A$1919,"<="&EOMONTH($A21,0)) | F21: =SUMIFS(Dados!$I$1:$I$1919,Dados!$K$1:$K$1919,Tp.Despesas!F$7,Dados!$A$1:$A$1919,">="&$A21,Dados!$A$1:$A$1919,"<="&EOMONTH($A21,0)) | G21: =SUMIFS(Dados!$I$1:$I$1919,Dados!$K$1:$K$1919,Tp.Despesas!G$7,Dados!$A$1:$A$1919,">="&$A21,Dados!$A$1:$A$1919,"<="&EOMONTH($A21,0)) | H21: =SUMIFS(Dados!$I$1:$I$1919,Dados!$K$1:$K$1919,Tp.Despesas!H$7,Dados!$A$1:$A$1919,">="&$A21,Dados!$A$1:$A$1919,"<="&EOMONTH($A21,0)) | I21: =SUMIFS(Dados!$I$1:$I$1919,Dados!$K$1:$K$1919,Tp.Despesas!I$7,Dados!$A$1:$A$1919,">="&$A21,Dados!$A$1:$A$1919,"<="&EOMONTH($A21,0)) | J21: =SUM(C21:I21)
... A44: =EOMONTH(A43,1)-DAY(EOMONTH(A43,1))+1 | C44: =SUMIFS(Dados!$I$1:$I$1919,Dados!$K$1:$K$1919,Tp.Despesas!C$7,Dados!$A$1:$A$1919,">="&$A44,Dados!$A$1:$A$1919,"<="&EOMONTH($A44,0)) | D44: =SUMIFS(Dados!$I$1:$I$1919,Dados!$K$1:$K$1919,Tp.Despesas!D$7,Dados!$A$1:$A$1919,">="&$A44,Dados!$A$1:$A$1919,"<="&EOMONTH($A44,0)) | E44: =SUMIFS(Dados!$I$1:$I$1919,Dados!$K$1:$K$1919,Tp.Despesas!E$7,Dados!$A$1:$A$1919,">="&$A44,Dados!$A$1:$A$1919,"<="&EOMONTH($A44,0)) | F44: =SUMIFS(Dados!$I$1:$I$1919,Dados!$K$1:$K$1919,Tp.Despesas!F$7,Dados!$A$1:$A$1919,">="&$A44,Dados!$A$1:$A$1919,"<="&EOMONTH($A44,0)) | G44: =SUMIFS(Dados!$I$1:$I$1919,Dados!$K$1:$K$1919,Tp.Despesas!G$7,Dados!$A$1:$A$1919,">="&$A44,Dados!$A$1:$A$1919,"<="&EOMONTH($A44,0)) | H44: =SUMIFS(Dados!$I$1:$I$1919,Dados!$K$1:$K$1919,Tp.Despesas!H$7,Dados!$A$1:$A$1919,">="&$A44,Dados!$A$1:$A$1919,"<="&EOMONTH($A44,0)) | I44: =SUMIFS(Dados!$I$1:$I$1919,Dados!$K$1:$K$1919,Tp.Despesas!I$7,Dados!$A$1:$A$1919,">="&$A44,Dados!$A$1:$A$1919,"<="&EOMONTH($A44,0)) | J44: =SUM(C44:I44)
A45: TOTAL GERAL | C45: =SUM(C9:C44) | D45: =SUM(D9:D44) | E45: =SUM(E9:E44) | F45: =SUM(F9:F44) | G45: =SUM(G9:G44) | H45: =SUM(H9:H44) | I45: =SUM(I9:I44) | J45: =SUM(J9:J44)
C46: =C45/$J$45 | D46: =D45/$J$45 | E46: =E45/$J$45 | F46: =F45/$J$45 | G46: =G45/$J$45 | H46: =H45/$J$45 | I46: =I45/$J$45 | J46: =J45/$J$45
J48: =RESUMO!L80
J49: =J48-J45

Sheet Contratos_ADM
A1: CONTRATOS | G1: ADMINISTRADORES_CONTRATO | N1: ADITIVOS | R1: ADMINISTRADORES_ADITIVO | Y1: PARCELAS
A2: Nº Contrato | B2: Data Início | C2: Data Fim | D2: Status | E2: Observações | G2: Nº Contrato | H2: CNPJ/CPF | I2: Nome/Razão Social | J2: Tipo | K2: Valor/Percentual | L2: Valor Total | M2: Nº Parcelas | N2: Nº Contrato | O2: Nº Aditivo | P2: Data Início | Q2: Data Fim | R2: Nº Contrato | S2: Nº Aditivo | T2: CNPJ/CPF | U2: Nome/Razão Social | V2: Tipo | W2: Valor/Percentual | X2: Valor Total | Y2: Referência | Z2: Número | AA2: CNPJ/CPF | AB2: Data Vencimento | AC2: Valor | AD2: Status
A3: 2024/010 | B3: 45540 | C3: 46635 | D3: ATIVO
G4: 2024/010 | H4: 30104762000107 | I4: VASCONCELOS & RINALDI ENGENHARIA | J4: Percentual | K4: 13
